Workbook

Sheet Recap
A1: ROLLING THREE MONTHS
A2: Agent | B2: Total Policies | C2: Manager | D2: Founded | E2: Partially Founded | F2: Unfounded | G2: Unfounded, coaching opportunities present | H2: Total | I2: Complaint Percentage
A3: Kylie DeMarino | B3: =COUNTIFS(policies[[Effective Date ]],">="&EOMONTH(TODAY(),-3)+1,policies[[Effective Date ]],"<="&EOMONTH(TODAY(),0),policies[Column3],Summary[[#This Row],[Agent]]) -> 133 | C3: John Tellez | D3: =COUNTIFS(Results[Agent],Summary[[#This Row],[Agent]],Results[Reviewed Date],">="&EOMONTH(TODAY(),-3)+1,Results[Reviewed Date],"<="&EOMONTH(TODAY(),0),Results[Determination],"Founded") -> 3 | E3: =COUNTIFS(Results[Agent],Summary[[#This Row],[Agent]],Results[Reviewed Date],">="&EOMONTH(TODAY(),-3)+1,Results[Reviewed Date],"<="&EOMONTH(TODAY(),0),Results[Determination],"Partially Founded") -> 2 | F3: =COUNTIFS(Results[Agent],Summary[[#This Row],[Agent]],Results[Reviewed Date],">="&EOMONTH(TODAY(),-3)+1,Results[Reviewed Date],"<="&EOMONTH(TODAY(),0),Results[Determination],"Unfounded") -> 0 | G3: =COUNTIFS(Results[Agent],Summary[[#This Row],[Agent]],Results[Reviewed Date],">="&EOMONTH(TODAY(),-3)+1,Results[Reviewed Date],"<="&EOMONTH(TODAY(),0),Results[Determination],"Unfounded, coaching opportunities present") -> 1 | H3: =COUNTIFS(Results[Agent],Summary[[#This Row],[Agent]],Results[Reviewed Date],">="&EOMONTH(TODAY(),-3)+1,Results[Reviewed Date],"<="&EOMONTH(TODAY(),0)) -> 6 | I3: =IFERROR(Summary[[#This Row],[Total]]/Summary[[#This Row],[Total Policies]],"") -> 0.045112782
A4: Gabriela Rivera | B4: =COUNTIFS(policies[[Effective Date ]],">="&EOMONTH(TODAY(),-3)+1,policies[[Effective Date ]],"<="&EOMONTH(TODAY(),0),policies[Column3],Summary[[#This Row],[Agent]]) -> 86 | C4: Nesia Jefferies | D4: =COUNTIFS(Results[Agent],Summary[[#This Row],[Agent]],Results[Reviewed Date],">="&EOMONTH(TODAY(),-3)+1,Results[Reviewed Date],"<="&EOMONTH(TODAY(),0),Results[Determination],"Founded") -> 3 | E4: =COUNTIFS(Results[Agent],Summary[[#This Row],[Agent]],Results[Reviewed Date],">="&EOMONTH(TODAY(),-3)+1,Results[Reviewed Date],"<="&EOMONTH(TODAY(),0),Results[Determination],"Partially Founded") -> 1 | F4: =COUNTIFS(Results[Agent],Summary[[#This Row],[Agent]],Results[Reviewed Date],">="&EOMONTH(TODAY(),-3)+1,Results[Reviewed Date],"<="&EOMONTH(TODAY(),0),Results[Determination],"Unfounded") -> 0 | G4: =COUNTIFS(Results[Agent],Summary[[#This Row],[Agent]],Results[Reviewed Date],">="&EOMONTH(TODAY(),-3)+1,Results[Reviewed Date],"<="&EOMONTH(TODAY(),0),Results[Determination],"Unfounded, coaching opportunities present") -> 0 | H4: =COUNTIFS(Results[Agent],Summary[[#This Row],[Agent]],Results[Reviewed Date],">="&EOMONTH(TODAY(),-3)+1,Results[Reviewed Date],"<="&EOMONTH(TODAY(),0)) -> 4 | I4: =IFERROR(Summary[[#This Row],[Total]]/Summary[[#This Row],[Total Policies]],"") -> 0.046511628
A5: Robert Lang | B5: =COUNTIFS(policies[[Effective Date ]],">="&EOMONTH(TODAY(),-3)+1,policies[[Effective Date ]],"<="&EOMONTH(TODAY(),0),policies[Column3],Summary[[#This Row],[Agent]]) -> 94 | C5: Nesia Jefferies | D5: =COUNTIFS(Results[Agent],Summary[[#This Row],[Agent]],Results[Reviewed Date],">="&EOMONTH(TODAY(),-3)+1,Results[Reviewed Date],"<="&EOMONTH(TODAY(),0),Results[Determination],"Founded") -> 3 | E5: =COUNTIFS(Results[Agent],Summary[[#This Row],[Agent]],Results[Reviewed Date],">="&EOMONTH(TODAY(),-3)+1,Results[Reviewed Date],"<="&EOMONTH(TODAY(),0),Results[Determination],"Partially Founded") -> 0 | F5: =COUNTIFS(Results[Agent],Summary[[#This Row],[Agent]],Results[Reviewed Date],">="&EOMONTH(TODAY(),-3)+1,Results[Reviewed Date],"<="&EOMONTH(TODAY(),0),Results[Determination],"Unfounded") -> 0 | G5: =COUNTIFS(Results[Agent],Summary[[#This Row],[Agent]],Results[Reviewed Date],">="&EOMONTH(TODAY(),-3)+1,Results[Reviewed Date],"<="&EOMONTH(TODAY(),0),Results[Determination],"Unfounded, coaching opportunities present") -> 0 | H5: =COUNTIFS(Results[Agent],Summary[[#This Row],[Agent]],Results[Reviewed Date],">="&EOMONTH(TODAY(),-3)+1,Results[Reviewed Date],"<="&EOMONTH(TODAY(),0)) -> 3 | I5: =IFERROR(Summary[[#This Row],[Total]]/Summary[[#This Row],[Total Policies]],"") -> 0.031914894
A6: Tonja Howard | B6: =COUNTIFS(policies[[Effective Date ]],">="&EOMONTH(TODAY(),-3)+1,policies[[Effective Date ]],"<="&EOMONTH(TODAY(),0),policies[Column3],Summary[[#This Row],[Agent]]) -> 115 | C6: Brian Henderson | D6: =COUNTIFS(Results[Agent],Summary[[#This Row],[Agent]],Results[Reviewed Date],">="&EOMONTH(TODAY(),-3)+1,Results[Reviewed Date],"<="&EOMONTH(TODAY(),0),Results[Determination],"Founded") -> 2 | E6: =COUNTIFS(Results[Agent],Summary[[#This Row],[Agent]],Results[Reviewed Date],">="&EOMONTH(TODAY(),-3)+1,Results[Reviewed Date],"<="&EOMONTH(TODAY(),0),Results[Determination],"Partially Founded") -> 1 | F6: =COUNTIFS(Results[Agent],Summary[[#This Row],[Agent]],Results[Reviewed Date],">="&EOMONTH(TODAY(),-3)+1,Results[Reviewed Date],"<="&EOMONTH(TODAY(),0),Results[Determination],"Unfounded") -> 0 | G6: =COUNTIFS(Results[Agent],Summary[[#This Row],[Agent]],Results[Reviewed Date],">="&EOMONTH(TODAY(),-3)+1,Results[Reviewed Date],"<="&EOMONTH(TODAY(),0),Results[Determination],"Unfounded, coaching opportunities present") -> 1 | H6: =COUNTIFS(Results[Agent],Summary[[#This Row],[Agent]],Results[Reviewed Date],">="&EOMONTH(TODAY(),-3)+1,Results[Reviewed Date],"<="&EOMONTH(TODAY(),0)) -> 4 | I6: =IFERROR(Summary[[#This Row],[Total]]/Summary[[#This Row],[Total Policies]],"") -> 0.034782609
A7: Whitney Benoit | B7: =COUNTIFS(policies[[Effective Date ]],">="&EOMONTH(TODAY(),-3)+1,policies[[Effective Date ]],"<="&EOMONTH(TODAY(),0),policies[Column3],Summary[[#This Row],[Agent]]) -> 97 | C7: Brian Henderson | D7: =COUNTIFS(Results[Agent],Summary[[#This Row],[Agent]],Results[Reviewed Date],">="&EOMONTH(TODAY(),-3)+1,Results[Reviewed Date],"<="&EOMONTH(TODAY(),0),Results[Determination],"Founded") -> 2 | E7: =COUNTIFS(Results[Agent],Summary[[#This Row],[Agent]],Results[Reviewed Date],">="&EOMONTH(TODAY(),-3)+1,Results[Reviewed Date],"<="&EOMONTH(TODAY(),0),Results[Determination],"Partially Founded") -> 1 | F7: =COUNTIFS(Results[Agent],Summary[[#This Row],[Agent]],Results[Reviewed Date],">="&EOMONTH(TODAY(),-3)+1,Results[Reviewed Date],"<="&EOMONTH(TODAY(),0),Results[Determination],"Unfounded") -> 0 | G7: =COUNTIFS(Results[Agent],Summary[[#This Row],[Agent]],Results[Reviewed Date],">="&EOMONTH(TODAY(),-3)+1,Results[Reviewed Date],"<="&EOMONTH(TODAY(),0),Results[Determination],"Unfounded, coaching opportunities present") -> 0 | H7: =COUNTIFS(Results[Agent],Summary[[#This Row],[Agent]],Results[Reviewed Date],">="&EOMONTH(TODAY(),-3)+1,Results[Reviewed Date],"<="&EOMONTH(TODAY(),0)) -> 3 | I7: =IFERROR(Summary[[#This Row],[Total]]/Summary[[#This Row],[Total Policies]],"") -> 0.030927835
A8: Christina Nguyen | B8: =COUNTIFS(policies[[Effective Date ]],">="&EOMONTH(TODAY(),-3)+1,policies[[Effective Date ]],"<="&EOMONTH(TODAY(),0),policies[Column3],Summary[[#This Row],[Agent]]) -> 90 | C8: Nesia Jefferies | D8: =COUNTIFS(Results[Agent],Summary[[#This Row],[Agent]],Results[Reviewed Date],">="&EOMONTH(TODAY(),-3)+1,Results[Reviewed Date],"<="&EOMONTH(TODAY(),0),Results[Determination],"Founded") -> 2 | E8: =COUNTIFS(Results[Agent],Summary[[#This Row],[Agent]],Results[Reviewed Date],">="&EOMONTH(TODAY(),-3)+1,Results[Reviewed Date],"<="&EOMONTH(TODAY(),0),Results[Determination],"Partially Founded") -> 0 | F8: =COUNTIFS(Results[Agent],Summary[[#This Row],[Agent]],Results[Reviewed Date],">="&EOMONTH(TODAY(),-3)+1,Results[Reviewed Date],"<="&EOMONTH(TODAY(),0),Results[Determination],"Unfounded") -> 0 | G8: =COUNTIFS(Results[Agent],Summary[[#This Row],[Agent]],Results[Reviewed Date],">="&EOMONTH(TODAY(),-3)+1,Results[Reviewed Date],"<="&EOMONTH(TODAY(),0),Results[Determination],"Unfounded, coaching opportunities present") -> 1 | H8: =COUNTIFS(Results[Agent],Summary[[#This Row],[Agent]],Results[Reviewed Date],">="&EOMONTH(TODAY(),-3)+1,Results[Reviewed Date],"<="&EOMONTH(TODAY(),0)) -> 3 | I8: =IFERROR(Summary[[#This Row],[Total]]/Summary[[#This Row],[Total Policies]],"") -> 0.033333333
A9: Robin O'Quin | B9: =COUNTIFS(policies[[Effective Date ]],">="&EOMONTH(TODAY(),-3)+1,policies[[Effective Date ]],"<="&EOMONTH(TODAY(),0),policies[Column3],Summary[[#This Row],[Agent]]) -> 0 | C9: Brian Henderson | D9: =COUNTIFS(Results[Agent],Summary[[#This Row],[Agent]],Results[Reviewed Date],">="&EOMONTH(TODAY(),-3)+1,Results[Reviewed Date],"<="&EOMONTH(TODAY(),0),Results[Determination],"Founded") -> 2 | E9: =COUNTIFS(Results[Agent],Summary[[#This Row],[Agent]],Results[Reviewed Date],">="&EOMONTH(TODAY(),-3)+1,Results[Reviewed Date],"<="&EOMONTH(TODAY(),0),Results[Determination],"Partially Founded") -> 0 | F9: =COUNTIFS(Results[Agent],Summary[[#This Row],[Agent]],Results[Reviewed Date],">="&EOMONTH(TODAY(),-3)+1,Results[Reviewed Date],"<="&EOMONTH(TODAY(),0),Results[Determination],"Unfounded") -> 0 | G9: =COUNTIFS(Results[Agent],Summary[[#This Row],[Agent]],Results[Reviewed Date],">="&EOMONTH(TODAY(),-3)+1,Results[Reviewed Date],"<="&EOMONTH(TODAY(),0),Results[Determination],"Unfounded, coaching opportunities present") -> 0 | H9: =COUNTIFS(Results[Agent],Summary[[#This Row],[Agent]],Results[Reviewed Date],">="&EOMONTH(TODAY(),-3)+1,Results[Reviewed Date],"<="&EOMONTH(TODAY(),0)) -> 2 | I9: =IFERROR(Summary[[#This Row],[Total]]/Summary[[#This Row],[Total Policies]],"")
A10: Ryan Lefler | B10: =COUNTIFS(policies[[Effective Date ]],">="&EOMONTH(TODAY(),-3)+1,policies[[Effective Date ]],"<="&EOMONTH(TODAY(),0),policies[Column3],Summary[[#This Row],[Agent]]) -> 83 | C10: Brian Henderson | D10: =COUNTIFS(Results[Agent],Summary[[#This Row],[Agent]],Results[Reviewed Date],">="&EOMONTH(TODAY(),-3)+1,Results[Reviewed Date],"<="&EOMONTH(TODAY(),0),Results[Determination],"Founded") -> 2 | E10: =COUNTIFS(Results[Agent],Summary[[#This Row],[Agent]],Results[Reviewed Date],">="&EOMONTH(TODAY(),-3)+1,Results[Reviewed Date],"<="&EOMONTH(TODAY(),0),Results[Determination],"Partially Founded") -> 0 | F10: =COUNTIFS(Results[Agent],Summary[[#This Row],[Agent]],Results[Reviewed Date],">="&EOMONTH(TODAY(),-3)+1,Results[Reviewed Date],"<="&EOMONTH(TODAY(),0),Results[Determination],"Unfounded") -> 0 | G10: =COUNTIFS(Results[Agent],Summary[[#This Row],[Agent]],Results[Reviewed Date],">="&EOMONTH(TODAY(),-3)+1,Results[Reviewed Date],"<="&EOMONTH(TODAY(),0),Results[Determination],"Unfounded, coaching opportunities present") -> 0 | H10: =COUNTIFS(Results[Agent],Summary[[#This Row],[Agent]],Results[Reviewed Date],">="&EOMONTH(TODAY(),-3)+1,Results[Reviewed Date],"<="&EOMONTH(TODAY(),0)) -> 2 | I10: =IFERROR(Summary[[#This Row],[Total]]/Summary[[#This Row],[Total Policies]],"") -> 0.024096386
A11: Victor Filimonchuk | B11: =COUNTIFS(policies[[Effective Date ]],">="&EOMONTH(TODAY(),-3)+1,policies[[Effective Date ]],"<="&EOMONTH(TODAY(),0),policies[Column3],Summary[[#This Row],[Agent]]) -> 67 | C11: John Tellez | D11: =COUNTIFS(Results[Agent],Summary[[#This Row],[Agent]],Results[Reviewed Date],">="&EOMONTH(TODAY(),-3)+1,Results[Reviewed Date],"<="&EOMONTH(TODAY(),0),Results[Determination],"Founded") -> 2 | E11: =COUNTIFS(Results[Agent],Summary[[#This Row],[Agent]],Results[Reviewed Date],">="&EOMONTH(TODAY(),-3)+1,Results[Reviewed Date],"<="&EOMONTH(TODAY(),0),Results[Determination],"Partially Founded") -> 0 | F11: =COUNTIFS(Results[Agent],Summary[[#This Row],[Agent]],Results[Reviewed Date],">="&EOMONTH(TODAY(),-3)+1,Results[Reviewed Date],"<="&EOMONTH(TODAY(),0),Results[Determination],"Unfounded") -> 0 | G11: =COUNTIFS(Results[Agent],Summary[[#This Row],[Agent]],Results[Reviewed Date],">="&EOMONTH(TODAY(),-3)+1,Results[Reviewed Date],"<="&EOMONTH(TODAY(),0),Results[Determination],"Unfounded, coaching opportunities present") -> 0 | H11: =COUNTIFS(Results[Agent],Summary[[#This Row],[Agent]],Results[Reviewed Date],">="&EOMONTH(TODAY(),-3)+1,Results[Reviewed Date],"<="&EOMONTH(TODAY(),0)) -> 2 | I11: =IFERROR(Summary[[#This Row],[Total]]/Summary[[#This Row],[Total Policies]],"") -> 0.029850746
A12: Vidal Fakondo | B12: =COUNTIFS(policies[[Effective Date ]],">="&EOMONTH(TODAY(),-3)+1,policies[[Effective Date ]],"<="&EOMONTH(TODAY(),0),policies[Column3],Summary[[#This Row],[Agent]]) -> 53 | C12: Brian Henderson | D12: =COUNTIFS(Results[Agent],Summary[[#This Row],[Agent]],Results[Reviewed Date],">="&EOMONTH(TODAY(),-3)+1,Results[Reviewed Date],"<="&EOMONTH(TODAY(),0),Results[Determination],"Founded") -> 2 | E12: =COUNTIFS(Results[Agent],Summary[[#This Row],[Agent]],Results[Reviewed Date],">="&EOMONTH(TODAY(),-3)+1,Results[Reviewed Date],"<="&EOMONTH(TODAY(),0),Results[Determination],"Partially Founded") -> 0 | F12: =COUNTIFS(Results[Agent],Summary[[#This Row],[Agent]],Results[Reviewed Date],">="&EOMONTH(TODAY(),-3)+1,Results[Reviewed Date],"<="&EOMONTH(TODAY(),0),Results[Determination],"Unfounded") -> 0 | G12: =COUNTIFS(Results[Agent],Summary[[#This Row],[Agent]],Results[Reviewed Date],">="&EOMONTH(TODAY(),-3)+1,Results[Reviewed Date],"<="&EOMONTH(TODAY(),0),Results[Determination],"Unfounded, coaching opportunities present") -> 0 | H12: =COUNTIFS(Results[Agent],Summary[[#This Row],[Agent]],Results[Reviewed Date],">="&EOMONTH(TODAY(),-3)+1,Results[Reviewed Date],"<="&EOMONTH(TODAY(),0)) -> 2 | I12: =IFERROR(Summary[[#This Row],[Total]]/Summary[[#This Row],[Total Policies]],"") -> 0.037735849
A13: Gary Johnson | B13: =COUNTIFS(policies[[Effective Date ]],">="&EOMONTH(TODAY(),-3)+1,policies[[Effective Date ]],"<="&EOMONTH(TODAY(),0),policies[Column3],Summary[[#This Row],[Agent]]) -> 53 | C13: Nesia Jefferies | D13: =COUNTIFS(Results[Agent],Summary[[#This Row],[Agent]],Results[Reviewed Date],">="&EOMONTH(TODAY(),-3)+1,Results[Reviewed Date],"<="&EOMONTH(TODAY(),0),Results[Determination],"Founded") -> 1 | E13: =COUNTIFS(Results[Agent],Summary[[#This Row],[Agent]],Results[Reviewed Date],">="&EOMONTH(TODAY(),-3)+1,Results[Reviewed Date],"<="&EOMONTH(TODAY(),0),Results[Determination],"Partially Founded") -> 0 | F13: =COUNTIFS(Results[Agent],Summary[[#This Row],[Agent]],Results[Reviewed Date],">="&EOMONTH(TODAY(),-3)+1,Results[Reviewed Date],"<="&EOMONTH(TODAY(),0),Results[Determination],"Unfounded") -> 1 | G13: =COUNTIFS(Results[Agent],Summary[[#This Row],[Agent]],Results[Reviewed Date],">="&EOMONTH(TODAY(),-3)+1,Results[Reviewed Date],"<="&EOMONTH(TODAY(),0),Results[Determination],"Unfounded, coaching opportunities present") -> 0 | H13: =COUNTIFS(Results[Agent],Summary[[#This Row],[Agent]],Results[Reviewed Date],">="&EOMONTH(TODAY(),-3)+1,Results[Reviewed Date],"<="&EOMONTH(TODAY(),0)) -> 2 | I13: =IFERROR(Summary[[#This Row],[Total]]/Summary[[#This Row],[Total Policies]],"") -> 0.037735849
A14: Aleccia Wright | B14: =COUNTIFS(policies[[Effective Date ]],">="&EOMONTH(TODAY(),-3)+1,policies[[Effective Date ]],"<="&EOMONTH(TODAY(),0),policies[Column3],Summary[[#This Row],[Agent]]) -> 67 | C14: Brian Henderson | D14: =COUNTIFS(Results[Agent],Summary[[#This Row],[Agent]],Results[Reviewed Date],">="&EOMONTH(TODAY(),-3)+1,Results[Reviewed Date],"<="&EOMONTH(TODAY(),0),Results[Determination],"Founded") -> 1 | E14: =COUNTIFS(Results[Agent],Summary[[#This Row],[Agent]],Results[Reviewed Date],">="&EOMONTH(TODAY(),-3)+1,Results[Reviewed Date],"<="&EOMONTH(TODAY(),0),Results[Determination],"Partially Founded") -> 0 | F14: =COUNTIFS(Results[Agent],Summary[[#This Row],[Agent]],Results[Reviewed Date],">="&EOMONTH(TODAY(),-3)+1,Results[Reviewed Date],"<="&EOMONTH(TODAY(),0),Results[Determination],"Unfounded") -> 0 | G14: =COUNTIFS(Results[Agent],Summary[[#This Row],[Agent]],Results[Reviewed Date],">="&EOMONTH(TODAY(),-3)+1,Results[Reviewed Date],"<="&EOMONTH(TODAY(),0),Results[Determination],"Unfounded, coaching opportunities present") -> 0 | H14: =COUNTIFS(Results[Agent],Summary[[#This Row],[Agent]],Results[Reviewed Date],">="&EOMONTH(TODAY(),-3)+1,Results[Reviewed Date],"<="&EOMONTH(TODAY(),0)) -> 1 | I14: =IFERROR(Summary[[#This Row],[Total]]/Summary[[#This Row],[Total Policies]],"") -> 0.014925373
... A22: Andrea Morris | B22: =COUNTIFS(policies[[Effective Date ]],">="&EOMONTH(TODAY(),-3)+1,policies[[Effective Date ]],"<="&EOMONTH(TODAY(),0),policies[Column3],Summary[[#This Row],[Agent]]) -> 105 | C22: John Tellez | D22: =COUNTIFS(Results[Agent],Summary[[#This Row],[Agent]],Results[Reviewed Date],">="&EOMONTH(TODAY(),-3)+1,Results[Reviewed Date],"<="&EOMONTH(TODAY(),0),Results[Determination],"Founded") -> 0 | E22: =COUNTIFS(Results[Agent],Summary[[#This Row],[Agent]],Results[Reviewed Date],">="&EOMONTH(TODAY(),-3)+1,Results[Reviewed Date],"<="&EOMONTH(TODAY(),0),Results[Determination],"Partially Founded") -> 0 | F22: =COUNTIFS(Results[Agent],Summary[[#This Row],[Agent]],Results[Reviewed Date],">="&EOMONTH(TODAY(),-3)+1,Results[Reviewed Date],"<="&EOMONTH(TODAY(),0),Results[Determination],"Unfounded") -> 0 | G22: =COUNTIFS(Results[Agent],Summary[[#This Row],[Agent]],Results[Reviewed Date],">="&EOMONTH(TODAY(),-3)+1,Results[Reviewed Date],"<="&EOMONTH(TODAY(),0),Results[Determination],"Unfounded, coaching opportunities present") -> 0 | H22: =COUNTIFS(Results[Agent],Summary[[#This Row],[Agent]],Results[Reviewed Date],">="&EOMONTH(TODAY(),-3)+1,Results[Reviewed Date],"<="&EOMONTH(TODAY(),0)) -> 0 | I22: =IFERROR(Summary[[#This Row],[Total]]/Summary[[#This Row],[Total Policies]],"") -> 0
A23: Asia Vann | B23: =COUNTIFS(policies[[Effective Date ]],">="&EOMONTH(TODAY(),-3)+1,policies[[Effective Date ]],"<="&EOMONTH(TODAY(),0),policies[Column3],Summary[[#This Row],[Agent]]) -> 64 | C23: Brian Henderson | D23: =COUNTIFS(Results[Agent],Summary[[#This Row],[Agent]],Results[Reviewed Date],">="&EOMONTH(TODAY(),-3)+1,Results[Reviewed Date],"<="&EOMONTH(TODAY(),0),Results[Determination],"Founded") -> 0 | E23: =COUNTIFS(Results[Agent],Summary[[#This Row],[Agent]],Results[Reviewed Date],">="&EOMONTH(TODAY(),-3)+1,Results[Reviewed Date],"<="&EOMONTH(TODAY(),0),Results[Determination],"Partially Founded") -> 0 | F23: =COUNTIFS(Results[Agent],Summary[[#This Row],[Agent]],Results[Reviewed Date],">="&EOMONTH(TODAY(),-3)+1,Results[Reviewed Date],"<="&EOMONTH(TODAY(),0),Results[Determination],"Unfounded") -> 0 | G23: =COUNTIFS(Results[Agent],Summary[[#This Row],[Agent]],Results[Reviewed Date],">="&EOMONTH(TODAY(),-3)+1,Results[Reviewed Date],"<="&EOMONTH(TODAY(),0),Results[Determination],"Unfounded, coaching opportunities present") -> 0 | H23: =COUNTIFS(Results[Agent],Summary[[#This Row],[Agent]],Results[Reviewed Date],">="&EOMONTH(TODAY(),-3)+1,Results[Reviewed Date],"<="&EOMONTH(TODAY(),0)) -> 0
A24: Bernie Livingston | B24: =COUNTIFS(policies[[Effective Date ]],">="&EOMONTH(TODAY(),-3)+1,policies[[Effective Date ]],"<="&EOMONTH(TODAY(),0),policies[Column3],Summary[[#This Row],[Agent]]) -> 76 | C24: Brian Henderson | D24: =COUNTIFS(Results[Agent],Summary[[#This Row],[Agent]],Results[Reviewed Date],">="&EOMONTH(TODAY(),-3)+1,Results[Reviewed Date],"<="&EOMONTH(TODAY(),0),Results[Determination],"Founded") -> 0 | E24: =COUNTIFS(Results[Agent],Summary[[#This Row],[Agent]],Results[Reviewed Date],">="&EOMONTH(TODAY(),-3)+1,Results[Reviewed Date],"<="&EOMONTH(TODAY(),0),Results[Determination],"Partially Founded") -> 0 | F24: =COUNTIFS(Results[Agent],Summary[[#This Row],[Agent]],Results[Reviewed Date],">="&EOMONTH(TODAY(),-3)+1,Results[Reviewed Date],"<="&EOMONTH(TODAY(),0),Results[Determination],"Unfounded") -> 0 | G24: =COUNTIFS(Results[Agent],Summary[[#This Row],[Agent]],Results[Reviewed Date],">="&EOMONTH(TODAY(),-3)+1,Results[Reviewed Date],"<="&EOMONTH(TODAY(),0),Results[Determination],"Unfounded, coaching opportunities present") -> 0 | H24: =COUNTIFS(Results[Agent],Summary[[#This Row],[Agent]],Results[Reviewed Date],">="&EOMONTH(TODAY(),-3)+1,Results[Reviewed Date],"<="&EOMONTH(TODAY(),0)) -> 0 | I24: =IFERROR(Summary[[#This Row],[Total]]/Summary[[#This Row],[Total Policies]],"") -> 0
A25: Carlos Vintimilla | B25: =COUNTIFS(policies[[Effective Date ]],">="&EOMONTH(TODAY(),-3)+1,policies[[Effective Date ]],"<="&EOMONTH(TODAY(),0),policies[Column3],Summary[[#This Row],[Agent]]) -> 0 | C25: Training | D25: =COUNTIFS(Results[Agent],Summary[[#This Row],[Agent]],Results[Reviewed Date],">="&EOMONTH(TODAY(),-3)+1,Results[Reviewed Date],"<="&EOMONTH(TODAY(),0),Results[Determination],"Founded") -> 0 | E25: =COUNTIFS(Results[Agent],Summary[[#This Row],[Agent]],Results[Reviewed Date],">="&EOMONTH(TODAY(),-3)+1,Results[Reviewed Date],"<="&EOMONTH(TODAY(),0),Results[Determination],"Partially Founded") -> 0 | F25: =COUNTIFS(Results[Agent],Summary[[#This Row],[Agent]],Results[Reviewed Date],">="&EOMONTH(TODAY(),-3)+1,Results[Reviewed Date],"<="&EOMONTH(TODAY(),0),Results[Determination],"Unfounded") -> 0 | G25: =COUNTIFS(Results[Agent],Summary[[#This Row],[Agent]],Results[Reviewed Date],">="&EOMONTH(TODAY(),-3)+1,Results[Reviewed Date],"<="&EOMONTH(TODAY(),0),Results[Determination],"Unfounded, coaching opportunities present") -> 0 | H25: =COUNTIFS(Results[Agent],Summary[[#This Row],[Agent]],Results[Reviewed Date],">="&EOMONTH(TODAY(),-3)+1,Results[Reviewed Date],"<="&EOMONTH(TODAY(),0)) -> 0 | I25: =IFERROR(Summary[[#This Row],[Total]]/Summary[[#This Row],[Total Policies]],"")
A26: Davis Khauka | B26: =COUNTIFS(policies[[Effective Date ]],">="&EOMONTH(TODAY(),-3)+1,policies[[Effective Date ]],"<="&EOMONTH(TODAY(),0),policies[Column3],Summary[[#This Row],[Agent]]) -> 80 | C26: John Tellez | D26: =COUNTIFS(Results[Agent],Summary[[#This Row],[Agent]],Results[Reviewed Date],">="&EOMONTH(TODAY(),-3)+1,Results[Reviewed Date],"<="&EOMONTH(TODAY(),0),Results[Determination],"Founded") -> 0 | E26: =COUNTIFS(Results[Agent],Summary[[#This Row],[Agent]],Results[Reviewed Date],">="&EOMONTH(TODAY(),-3)+1,Results[Reviewed Date],"<="&EOMONTH(TODAY(),0),Results[Determination],"Partially Founded") -> 0 | F26: =COUNTIFS(Results[Agent],Summary[[#This Row],[Agent]],Results[Reviewed Date],">="&EOMONTH(TODAY(),-3)+1,Results[Reviewed Date],"<="&EOMONTH(TODAY(),0),Results[Determination],"Unfounded") -> 0 | G26: =COUNTIFS(Results[Agent],Summary[[#This Row],[Agent]],Results[Reviewed Date],">="&EOMONTH(TODAY(),-3)+1,Results[Reviewed Date],"<="&EOMONTH(TODAY(),0),Results[Determination],"Unfounded, coaching opportunities present") -> 0 | H26: =COUNTIFS(Results[Agent],Summary[[#This Row],[Agent]],Results[Reviewed Date],">="&EOMONTH(TODAY(),-3)+1,Results[Reviewed Date],"<="&EOMONTH(TODAY(),0)) -> 0 | I26: =IFERROR(Summary[[#This Row],[Total]]/Summary[[#This Row],[Total Policies]],"") -> 0
A27: Earnestein Holton | B27: =COUNTIFS(policies[[Effective Date ]],">="&EOMONTH(TODAY(),-3)+1,policies[[Effective Date ]],"<="&EOMONTH(TODAY(),0),policies[Column3],Summary[[#This Row],[Agent]]) -> 19 | C27: John Tellez | D27: =COUNTIFS(Results[Agent],Summary[[#This Row],[Agent]],Results[Reviewed Date],">="&EOMONTH(TODAY(),-3)+1,Results[Reviewed Date],"<="&EOMONTH(TODAY(),0),Results[Determination],"Founded") -> 0 | E27: =COUNTIFS(Results[Agent],Summary[[#This Row],[Agent]],Results[Reviewed Date],">="&EOMONTH(TODAY(),-3)+1,Results[Reviewed Date],"<="&EOMONTH(TODAY(),0),Results[Determination],"Partially Founded") -> 0 | F27: =COUNTIFS(Results[Agent],Summary[[#This Row],[Agent]],Results[Reviewed Date],">="&EOMONTH(TODAY(),-3)+1,Results[Reviewed Date],"<="&EOMONTH(TODAY(),0),Results[Determination],"Unfounded") -> 0 | G27: =COUNTIFS(Results[Agent],Summary[[#This Row],[Agent]],Results[Reviewed Date],">="&EOMONTH(TODAY(),-3)+1,Results[Reviewed Date],"<="&EOMONTH(TODAY(),0),Results[Determination],"Unfounded, coaching opportunities present") -> 0 | H27: =COUNTIFS(Results[Agent],Summary[[#This Row],[Agent]],Results[Reviewed Date],">="&EOMONTH(TODAY(),-3)+1,Results[Reviewed Date],"<="&EOMONTH(TODAY(),0)) -> 0 | I27: =IFERROR(Summary[[#This Row],[Total]]/Summary[[#This Row],[Total Policies]],"") -> 0
A28: Jacob Michael Luffman | B28: =COUNTIFS(policies[[Effective Date ]],">="&EOMONTH(TODAY(),-3)+1,policies[[Effective Date ]],"<="&EOMONTH(TODAY(),0),policies[Column3],Summary[[#This Row],[Agent]]) -> 0 | C28: Training | D28: =COUNTIFS(Results[Agent],Summary[[#This Row],[Agent]],Results[Reviewed Date],">="&EOMONTH(TODAY(),-3)+1,Results[Reviewed Date],"<="&EOMONTH(TODAY(),0),Results[Determination],"Founded") -> 0 | E28: =COUNTIFS(Results[Agent],Summary[[#This Row],[Agent]],Results[Reviewed Date],">="&EOMONTH(TODAY(),-3)+1,Results[Reviewed Date],"<="&EOMONTH(TODAY(),0),Results[Determination],"Partially Founded") -> 0 | F28: =COUNTIFS(Results[Agent],Summary[[#This Row],[Agent]],Results[Reviewed Date],">="&EOMONTH(TODAY(),-3)+1,Results[Reviewed Date],"<="&EOMONTH(TODAY(),0),Results[Determination],"Unfounded") -> 0 | G28: =COUNTIFS(Results[Agent],Summary[[#This Row],[Agent]],Results[Reviewed Date],">="&EOMONTH(TODAY(),-3)+1,Results[Reviewed Date],"<="&EOMONTH(TODAY(),0),Results[Determination],"Unfounded, coaching opportunities present") -> 0 | H28: =COUNTIFS(Results[Agent],Summary[[#This Row],[Agent]],Results[Reviewed Date],">="&EOMONTH(TODAY(),-3)+1,Results[Reviewed Date],"<="&EOMONTH(TODAY(),0)) -> 0 | I28: =IFERROR(Summary[[#This Row],[Total]]/Summary[[#This Row],[Total Policies]],"")
A29: Jaeden Collins | B29: =COUNTIFS(policies[[Effective Date ]],">="&EOMONTH(TODAY(),-3)+1,policies[[Effective Date ]],"<="&EOMONTH(TODAY(),0),policies[Column3],Summary[[#This Row],[Agent]]) -> 17 | C29: Brian Henderson | D29: =COUNTIFS(Results[Agent],Summary[[#This Row],[Agent]],Results[Reviewed Date],">="&EOMONTH(TODAY(),-3)+1,Results[Reviewed Date],"<="&EOMONTH(TODAY(),0),Results[Determination],"Founded") -> 0 | E29: =COUNTIFS(Results[Agent],Summary[[#This Row],[Agent]],Results[Reviewed Date],">="&EOMONTH(TODAY(),-3)+1,Results[Reviewed Date],"<="&EOMONTH(TODAY(),0),Results[Determination],"Partially Founded") -> 0 | F29: =COUNTIFS(Results[Agent],Summary[[#This Row],[Agent]],Results[Reviewed Date],">="&EOMONTH(TODAY(),-3)+1,Results[Reviewed Date],"<="&EOMONTH(TODAY(),0),Results[Determination],"Unfounded") -> 0 | G29: =COUNTIFS(Results[Agent],Summary[[#This Row],[Agent]],Results[Reviewed Date],">="&EOMONTH(TODAY(),-3)+1,Results[Reviewed Date],"<="&EOMONTH(TODAY(),0),Results[Determination],"Unfounded, coaching opportunities present") -> 0 | H29: =COUNTIFS(Results[Agent],Summary[[#This Row],[Agent]],Results[Reviewed Date],">="&EOMONTH(TODAY(),-3)+1,Results[Reviewed Date],"<="&EOMONTH(TODAY(),0)) -> 0 | I29: =IFERROR(Summary[[#This Row],[Total]]/Summary[[#This Row],[Total Policies]],"") -> 0
A30: Jasmin Johnson | B30: =COUNTIFS(policies[[Effective Date ]],">="&EOMONTH(TODAY(),-3)+1,policies[[Effective Date ]],"<="&EOMONTH(TODAY(),0),policies[Column3],Summary[[#This Row],[Agent]]) -> 28 | C30: Nesia Jefferies | D30: =COUNTIFS(Results[Agent],Summary[[#This Row],[Agent]],Results[Reviewed Date],">="&EOMONTH(TODAY(),-3)+1,Results[Reviewed Date],"<="&EOMONTH(TODAY(),0),Results[Determination],"Founded") -> 0 | E30: =COUNTIFS(Results[Agent],Summary[[#This Row],[Agent]],Results[Reviewed Date],">="&EOMONTH(TODAY(),-3)+1,Results[Reviewed Date],"<="&EOMONTH(TODAY(),0),Results[Determination],"Partially Founded") -> 0 | F30: =COUNTIFS(Results[Agent],Summary[[#This Row],[Agent]],Results[Reviewed Date],">="&EOMONTH(TODAY(),-3)+1,Results[Reviewed Date],"<="&EOMONTH(TODAY(),0),Results[Determination],"Unfounded") -> 0 | G30: =COUNTIFS(Results[Agent],Summary[[#This Row],[Agent]],Results[Reviewed Date],">="&EOMONTH(TODAY(),-3)+1,Results[Reviewed Date],"<="&EOMONTH(TODAY(),0),Results[Determination],"Unfounded, coaching opportunities present") -> 0 | H30: =COUNTIFS(Results[Agent],Summary[[#This Row],[Agent]],Results[Reviewed Date],">="&EOMONTH(TODAY(),-3)+1,Results[Reviewed Date],"<="&EOMONTH(TODAY(),0)) -> 0 | I30: =IFERROR(Summary[[#This Row],[Total]]/Summary[[#This Row],[Total Policies]],"") -> 0
A31: Jeremiah Napper | B31: =COUNTIFS(policies[[Effective Date ]],">="&EOMONTH(TODAY(),-3)+1,policies[[Effective Date ]],"<="&EOMONTH(TODAY(),0),policies[Column3],Summary[[#This Row],[Agent]]) -> 0 | C31: Training | D31: =COUNTIFS(Results[Agent],Summary[[#This Row],[Agent]],Results[Reviewed Date],">="&EOMONTH(TODAY(),-3)+1,Results[Reviewed Date],"<="&EOMONTH(TODAY(),0),Results[Determination],"Founded") -> 0 | E31: =COUNTIFS(Results[Agent],Summary[[#This Row],[Agent]],Results[Reviewed Date],">="&EOMONTH(TODAY(),-3)+1,Results[Reviewed Date],"<="&EOMONTH(TODAY(),0),Results[Determination],"Partially Founded") -> 0 | F31: =COUNTIFS(Results[Agent],Summary[[#This Row],[Agent]],Results[Reviewed Date],">="&EOMONTH(TODAY(),-3)+1,Results[Reviewed Date],"<="&EOMONTH(TODAY(),0),Results[Determination],"Unfounded") -> 0 | G31: =COUNTIFS(Results[Agent],Summary[[#This Row],[Agent]],Results[Reviewed Date],">="&EOMONTH(TODAY(),-3)+1,Results[Reviewed Date],"<="&EOMONTH(TODAY(),0),Results[Determination],"Unfounded, coaching opportunities present") -> 0 | H31: =COUNTIFS(Results[Agent],Summary[[#This Row],[Agent]],Results[Reviewed Date],">="&EOMONTH(TODAY(),-3)+1,Results[Reviewed Date],"<="&EOMONTH(TODAY(),0)) -> 0 | I31: =IFERROR(Summary[[#This Row],[Total]]/Summary[[#This Row],[Total Policies]],"")
A32: Jessica Laster | B32: =COUNTIFS(policies[[Effective Date ]],">="&EOMONTH(TODAY(),-3)+1,policies[[Effective Date ]],"<="&EOMONTH(TODAY(),0),policies[Column3],Summary[[#This Row],[Agent]]) -> 31 | C32: Nesia Jefferies | D32: =COUNTIFS(Results[Agent],Summary[[#This Row],[Agent]],Results[Reviewed Date],">="&EOMONTH(TODAY(),-3)+1,Results[Reviewed Date],"<="&EOMONTH(TODAY(),0),Results[Determination],"Founded") -> 0 | E32: =COUNTIFS(Results[Agent],Summary[[#This Row],[Agent]],Results[Reviewed Date],">="&EOMONTH(TODAY(),-3)+1,Results[Reviewed Date],"<="&EOMONTH(TODAY(),0),Results[Determination],"Partially Founded") -> 0 | F32: =COUNTIFS(Results[Agent],Summary[[#This Row],[Agent]],Results[Reviewed Date],">="&EOMONTH(TODAY(),-3)+1,Results[Reviewed Date],"<="&EOMONTH(TODAY(),0),Results[Determination],"Unfounded") -> 0 | G32: =COUNTIFS(Results[Agent],Summary[[#This Row],[Agent]],Results[Reviewed Date],">="&EOMONTH(TODAY(),-3)+1,Results[Reviewed Date],"<="&EOMONTH(TODAY(),0),Results[Determination],"Unfounded, coaching opportunities present") -> 0 | H32: =COUNTIFS(Results[Agent],Summary[[#This Row],[Agent]],Results[Reviewed Date],">="&EOMONTH(TODAY(),-3)+1,Results[Reviewed Date],"<="&EOMONTH(TODAY(),0)) -> 0 | I32: =IFERROR(Summary[[#This Row],[Total]]/Summary[[#This Row],[Total Policies]],"") -> 0
A33: Jonathan Weary | B33: =COUNTIFS(policies[[Effective Date ]],">="&EOMONTH(TODAY(),-3)+1,policies[[Effective Date ]],"<="&EOMONTH(TODAY(),0),policies[Column3],Summary[[#This Row],[Agent]]) -> 0 | C33: Training | D33: =COUNTIFS(Results[Agent],Summary[[#This Row],[Agent]],Results[Reviewed Date],">="&EOMONTH(TODAY(),-3)+1,Results[Reviewed Date],"<="&EOMONTH(TODAY(),0),Results[Determination],"Founded") -> 0 | E33: =COUNTIFS(Results[Agent],Summary[[#This Row],[Agent]],Results[Reviewed Date],">="&EOMONTH(TODAY(),-3)+1,Results[Reviewed Date],"<="&EOMONTH(TODAY(),0),Results[Determination],"Partially Founded") -> 0 | F33: =COUNTIFS(Results[Agent],Summary[[#This Row],[Agent]],Results[Reviewed Date],">="&EOMONTH(TODAY(),-3)+1,Results[Reviewed Date],"<="&EOMONTH(TODAY(),0),Results[Determination],"Unfounded") -> 0 | G33: =COUNTIFS(Results[Agent],Summary[[#This Row],[Agent]],Results[Reviewed Date],">="&EOMONTH(TODAY(),-3)+1,Results[Reviewed Date],"<="&EOMONTH(TODAY(),0),Results[Determination],"Unfounded, coaching opportunities present") -> 0 | H33: =COUNTIFS(Results[Agent],Summary[[#This Row],[Agent]],Results[Reviewed Date],">="&EOMONTH(TODAY(),-3)+1,Results[Reviewed Date],"<="&EOMONTH(TODAY(),0)) -> 0 | I33: =IFERROR(Summary[[#This Row],[Total]]/Summary[[#This Row],[Total Policies]],"")
A34: Mandi Jones | B34: =COUNTIFS(policies[[Effective Date ]],">="&EOMONTH(TODAY(),-3)+1,policies[[Effective Date ]],"<="&EOMONTH(TODAY(),0),policies[Column3],Summary[[#This Row],[Agent]]) -> 1 | C34: Training | D34: =COUNTIFS(Results[Agent],Summary[[#This Row],[Agent]],Results[Reviewed Date],">="&EOMONTH(TODAY(),-3)+1,Results[Reviewed Date],"<="&EOMONTH(TODAY(),0),Results[Determination],"Founded") -> 0 | E34: =COUNTIFS(Results[Agent],Summary[[#This Row],[Agent]],Results[Reviewed Date],">="&EOMONTH(TODAY(),-3)+1,Results[Reviewed Date],"<="&EOMONTH(TODAY(),0),Results[Determination],"Partially Founded") -> 0 | F34: =COUNTIFS(Results[Agent],Summary[[#This Row],[Agent]],Results[Reviewed Date],">="&EOMONTH(TODAY(),-3)+1,Results[Reviewed Date],"<="&EOMONTH(TODAY(),0),Results[Determination],"Unfounded") -> 0 | G34: =COUNTIFS(Results[Agent],Summary[[#This Row],[Agent]],Results[Reviewed Date],">="&EOMONTH(TODAY(),-3)+1,Results[Reviewed Date],"<="&EOMONTH(TODAY(),0),Results[Determination],"Unfounded, coaching opportunities present") -> 0 | H34: =COUNTIFS(Results[Agent],Summary[[#This Row],[Agent]],Results[Reviewed Date],">="&EOMONTH(TODAY(),-3)+1,Results[Reviewed Date],"<="&EOMONTH(TODAY(),0)) -> 0 | I34: =IFERROR(Summary[[#This Row],[Total]]/Summary[[#This Row],[Total Policies]],"") -> 0
A35: Marvonique Watts-Golden | B35: =COUNTIFS(policies[[Effective Date ]],">="&EOMONTH(TODAY(),-3)+1,policies[[Effective Date ]],"<="&EOMONTH(TODAY(),0),policies[Column3],Summary[[#This Row],[Agent]]) -> 0 | C35: Training | D35: =COUNTIFS(Results[Agent],Summary[[#This Row],[Agent]],Results[Reviewed Date],">="&EOMONTH(TODAY(),-3)+1,Results[Reviewed Date],"<="&EOMONTH(TODAY(),0),Results[Determination],"Founded") -> 0 | E35: =COUNTIFS(Results[Agent],Summary[[#This Row],[Agent]],Results[Reviewed Date],">="&EOMONTH(TODAY(),-3)+1,Results[Reviewed Date],"<="&EOMONTH(TODAY(),0),Results[Determination],"Partially Founded") -> 0 | F35: =COUNTIFS(Results[Agent],Summary[[#This Row],[Agent]],Results[Reviewed Date],">="&EOMONTH(TODAY(),-3)+1,Results[Reviewed Date],"<="&EOMONTH(TODAY(),0),Results[Determination],"Unfounded") -> 0 | G35: =COUNTIFS(Results[Agent],Summary[[#This Row],[Agent]],Results[Reviewed Date],">="&EOMONTH(TODAY(),-3)+1,Results[Reviewed Date],"<="&EOMONTH(TODAY(),0),Results[Determination],"Unfounded, coaching opportunities present") -> 0 | H35: =COUNTIFS(Results[Agent],Summary[[#This Row],[Agent]],Results[Reviewed Date],">="&EOMONTH(TODAY(),-3)+1,Results[Reviewed Date],"<="&EOMONTH(TODAY(),0)) -> 0 | I35: =IFERROR(Summary[[#This Row],[Total]]/Summary[[#This Row],[Total Policies]],"")
... A48: Zachary Copley | B48: =COUNTIFS(policies[[Effective Date ]],">="&EOMONTH(TODAY(),-3)+1,policies[[Effective Date ]],"<="&EOMONTH(TODAY(),0),policies[Column3],Summary[[#This Row],[Agent]]) -> 0 | C48: Training | D48: =COUNTIFS(Results[Agent],Summary[[#This Row],[Agent]],Results[Reviewed Date],">="&EOMONTH(TODAY(),-3)+1,Results[Reviewed Date],"<="&EOMONTH(TODAY(),0),Results[Determination],"Founded") -> 0 | E48: =COUNTIFS(Results[Agent],Summary[[#This Row],[Agent]],Results[Reviewed Date],">="&EOMONTH(TODAY(),-3)+1,Results[Reviewed Date],"<="&EOMONTH(TODAY(),0),Results[Determination],"Partially Founded") -> 0 | F48: =COUNTIFS(Results[Agent],Summary[[#This Row],[Agent]],Results[Reviewed Date],">="&EOMONTH(TODAY(),-3)+1,Results[Reviewed Date],"<="&EOMONTH(TODAY(),0),Results[Determination],"Unfounded") -> 0 | G48: =COUNTIFS(Results[Agent],Summary[[#This Row],[Agent]],Results[Reviewed Date],">="&EOMONTH(TODAY(),-3)+1,Results[Reviewed Date],"<="&EOMONTH(TODAY(),0),Results[Determination],"Unfounded, coaching opportunities present") -> 0 | H48: =COUNTIFS(Results[Agent],Summary[[#This Row],[Agent]],Results[Reviewed Date],">="&EOMONTH(TODAY(),-3)+1,Results[Reviewed Date],"<="&EOMONTH(TODAY(),0)) -> 0 | I48: =IFERROR(Summary[[#This Row],[Total]]/Summary[[#This Row],[Total Policies]],"")
A49: Total | B49: =SUBTOTAL(109,Summary[Total Policies]) -> 2035 | D49: =SUBTOTAL(109,Summary[Founded]) -> 27 | E49: =SUBTOTAL(109,Summary[Partially Founded]) -> 7 | F49: =SUBTOTAL(109,Summary[Unfounded]) -> 1 | G49: =SUBTOTAL(109,Summary[Unfounded, coaching opportunities present]) -> 6 | H49: =SUBTOTAL(109,Summary[Total]) -> 41 | I49: =Summary[[#Totals],[Total]]/SUM(Summary[Total Policies]) -> 0.02014742
A52: Source | B52: Founded | C52: Partially Founded | D52: Unfounded | E52: Unfounded, coaching opportunities present | F52: Total
A53: Carrier | B53: =COUNTIFS(Results[Complaint Source],Table6[[#This Row],[Source]],Results[Reviewed Date],">="&EOMONTH(TODAY(),-3)+1,Results[Reviewed Date],"<="&EOMONTH(TODAY(),0),Results[Determination],"Founded") -> 9 | C53: =COUNTIFS(Results[Complaint Source],Table6[[#This Row],[Source]],Results[Reviewed Date],">="&EOMONTH(TODAY(),-3)+1,Results[Reviewed Date],"<="&EOMONTH(TODAY(),0),Results[Determination],"Partially Founded") -> 3 | D53: =COUNTIFS(Results[Complaint Source],Table6[[#This Row],[Source]],Results[Reviewed Date],">="&EOMONTH(TODAY(),-3)+1,Results[Reviewed Date],"<="&EOMONTH(TODAY(),0),Results[Determination],"Unfounded") -> 1 | E53: =COUNTIFS(Results[Complaint Source],Table6[[#This Row],[Source]],Results[Reviewed Date],">="&EOMONTH(TODAY(),-3)+1,Results[Reviewed Date],"<="&EOMONTH(TODAY(),0),Results[Determination],"Unfounded, coaching opportunities present") -> 3 | F53: =SUM(Table6[[#This Row],[Founded]:[Unfounded, coaching opportunities present]]) -> 16
A54: CTM | B54: =COUNTIFS(Results[Complaint Source],Table6[[#This Row],[Source]],Results[Reviewed Date],">="&EOMONTH(TODAY(),-3)+1,Results[Reviewed Date],"<="&EOMONTH(TODAY(),0),Results[Determination],"Founded") -> 3 | C54: =COUNTIFS(Results[Complaint Source],Table6[[#This Row],[Source]],Results[Reviewed Date],">="&EOMONTH(TODAY(),-3)+1,Results[Reviewed Date],"<="&EOMONTH(TODAY(),0),Results[Determination],"Partially Founded") -> 2 | D54: =COUNTIFS(Results[Complaint Source],Table6[[#This Row],[Source]],Results[Reviewed Date],">="&EOMONTH(TODAY(),-3)+1,Results[Reviewed Date],"<="&EOMONTH(TODAY(),0),Results[Determination],"Unfounded") -> 0 | E54: =COUNTIFS(Results[Complaint Source],Table6[[#This Row],[Source]],Results[Reviewed Date],">="&EOMONTH(TODAY(),-3)+1,Results[Reviewed Date],"<="&EOMONTH(TODAY(),0),Results[Determination],"Unfounded, coaching opportunities present") -> 0 | F54: =SUM(Table6[[#This Row],[Founded]:[Unfounded, coaching opportunities present]]) -> 5
A55: Member Services | B55: =COUNTIFS(Results[Complaint Source],Table6[[#This Row],[Source]],Results[Reviewed Date],">="&EOMONTH(TODAY(),-3)+1,Results[Reviewed Date],"<="&EOMONTH(TODAY(),0),Results[Determination],"Founded") -> 17 | C55: =COUNTIFS(Results[Complaint Source],Table6[[#This Row],[Source]],Results[Reviewed Date],">="&EOMONTH(TODAY(),-3)+1,Results[Reviewed Date],"<="&EOMONTH(TODAY(),0),Results[Determination],"Partially Founded") -> 2 | D55: =COUNTIFS(Results[Complaint Source],Table6[[#This Row],[Source]],Results[Reviewed Date],">="&EOMONTH(TODAY(),-3)+1,Results[Reviewed Date],"<="&EOMONTH(TODAY(),0),Results[Determination],"Unfounded") -> 1 | E55: =COUNTIFS(Results[Complaint Source],Table6[[#This Row],[Source]],Results[Reviewed Date],">="&EOMONTH(TODAY(),-3)+1,Results[Reviewed Date],"<="&EOMONTH(TODAY(),0),Results[Determination],"Unfounded, coaching opportunities present") -> 3 | F55: =SUM(Table6[[#This Row],[Founded]:[Unfounded, coaching opportunities present]]) -> 23
A56: Total | B56: =SUBTOTAL(109,Table6[Founded]) -> 29 | C56: =SUBTOTAL(109,Table6[Partially Founded]) -> 7 | D56: =SUBTOTAL(109,Table6[Unfounded]) -> 2 | E56: =SUBTOTAL(109,Table6[Unfounded, coaching opportunities present]) -> 6 | F56: =SUBTOTAL(109,Table6[Total]) -> 44
A59: Carrier | B59: Founded | C59: Partially Founded | D59: Unfounded | E59: Unfounded, coaching opportunities present | F59: Total
A60: Gold Kidney Health Plan | B60: =COUNTIFS(Results[Name of Carrier Enrolled],Recap!A63,Results[Reviewed Date],">="&EOMONTH(TODAY(),-3)+1,Results[Reviewed Date],"<="&EOMONTH(TODAY(),0),Results[Determination],"Founded") -> 4 | C60: =COUNTIFS(Results[Name of Carrier Enrolled],[1]Recap!A52,Results[Reviewed Date],">="&EOMONTH(TODAY(),-3)+1,Results[Reviewed Date],"<="&EOMONTH(TODAY(),0),Results[Determination],"Partially Founded") -> 5 | D60: =COUNTIFS(Results[Name of Carrier Enrolled],[1]Recap!A52,Results[Reviewed Date],">="&EOMONTH(TODAY(),-3)+1,Results[Reviewed Date],"<="&EOMONTH(TODAY(),0),Results[Determination],"Unfounded") -> 1 | E60: =COUNTIFS(Results[Name of Carrier Enrolled],[1]Recap!A52,Results[Reviewed Date],">="&EOMONTH(TODAY(),-3)+1,Results[Reviewed Date],"<="&EOMONTH(TODAY(),0),Results[Determination],"Unfounded, coaching opportunities present") -> 1 | F60: =SUM(B60:E60) -> 11
A61: Zing Health | B61: =COUNTIFS(Results[Name of Carrier Enrolled],Recap!A68,Results[Reviewed Date],">="&EOMONTH(TODAY(),-3)+1,Results[Reviewed Date],"<="&EOMONTH(TODAY(),0),Results[Determination],"Founded") -> 4 | C61: =COUNTIFS(Results[Name of Carrier Enrolled],[1]Recap!A57,Results[Reviewed Date],">="&EOMONTH(TODAY(),-3)+1,Results[Reviewed Date],"<="&EOMONTH(TODAY(),0),Results[Determination],"Partially Founded") -> 0 | D61: =COUNTIFS(Results[Name of Carrier Enrolled],[1]Recap!A57,Results[Reviewed Date],">="&EOMONTH(TODAY(),-3)+1,Results[Reviewed Date],"<="&EOMONTH(TODAY(),0),Results[Determination],"Unfounded") -> 0 | E61: =COUNTIFS(Results[Name of Carrier Enrolled],[1]Recap!A57,Results[Reviewed Date],">="&EOMONTH(TODAY(),-3)+1,Results[Reviewed Date],"<="&EOMONTH(TODAY(),0),Results[Determination],"Unfounded, coaching opportunities present") -> 0 | F61: =SUM(B61:E61) -> 4
A62: Cigna | B62: =COUNTIFS(Results[Name of Carrier Enrolled],Recap!A61,Results[Reviewed Date],">="&EOMONTH(TODAY(),-3)+1,Results[Reviewed Date],"<="&EOMONTH(TODAY(),0),Results[Determination],"Founded") -> 3 | C62: =COUNTIFS(Results[Name of Carrier Enrolled],[1]Recap!A50,Results[Reviewed Date],">="&EOMONTH(TODAY(),-3)+1,Results[Reviewed Date],"<="&EOMONTH(TODAY(),0),Results[Determination],"Partially Founded") -> 0 | D62: =COUNTIFS(Results[Name of Carrier Enrolled],[1]Recap!A50,Results[Reviewed Date],">="&EOMONTH(TODAY(),-3)+1,Results[Reviewed Date],"<="&EOMONTH(TODAY(),0),Results[Determination],"Unfounded") -> 1 | E62: =COUNTIFS(Results[Name of Carrier Enrolled],[1]Recap!A50,Results[Reviewed Date],">="&EOMONTH(TODAY(),-3)+1,Results[Reviewed Date],"<="&EOMONTH(TODAY(),0),Results[Determination],"Unfounded, coaching opportunities present") -> 2 | F62: =SUM(B62:E62) -> 6
A63: Devoted Health | B63: =COUNTIFS(Results[Name of Carrier Enrolled],Recap!A62,Results[Reviewed Date],">="&EOMONTH(TODAY(),-3)+1,Results[Reviewed Date],"<="&EOMONTH(TODAY(),0),Results[Determination],"Founded") -> 1 | C63: =COUNTIFS(Results[Name of Carrier Enrolled],[1]Recap!A51,Results[Reviewed Date],">="&EOMONTH(TODAY(),-3)+1,Results[Reviewed Date],"<="&EOMONTH(TODAY(),0),Results[Determination],"Partially Founded") -> 1 | D63: =COUNTIFS(Results[Name of Carrier Enrolled],[1]Recap!A51,Results[Reviewed Date],">="&EOMONTH(TODAY(),-3)+1,Results[Reviewed Date],"<="&EOMONTH(TODAY(),0),Results[Determination],"Unfounded") -> 0 | E63: =COUNTIFS(Results[Name of Carrier Enrolled],[1]Recap!A51,Results[Reviewed Date],">="&EOMONTH(TODAY(),-3)+1,Results[Reviewed Date],"<="&EOMONTH(TODAY(),0),Results[Determination],"Unfounded, coaching opportunities present") -> 1 | F63: =SUM(B63:E63) -> 3
...

Sheet Results
A1: Agent | B1: Manager | C1: AMS Link | D1: Application Date | E1: Complaint Date | F1: Due Date | G1: Reviewed Date | H1: Complaint Source | I1: Name of Carrier Enrolled | J1: Allegations | K1: Allegation Topic | L1: Determination | M1: AOIs | N1: Rationale | O1: Summary Link | P1: Coached | Q1: Date
A2: Christina Nguyen | B2: Nesia Jefferies | C2: https://app.agencybloc.com/individuals/72332476/detail | D2: 45992 | E2: 46035 | G2: 46048.428 | H2: Member Services | I2: Aetna Inc. | J2: The member states that they were misled about the food card. They state that they were that they would be getting $210. | K2: •SSBCI Benefits •Benefit Misinformation | L2: Founded | M2: •SSBCI Benefits •Benefit Misinformation •Drugs - Cost or Coverage | N2: Christina initially quotes the OTC benefit correctly. However, at approximately 48:01 into the call, she tells the member that there is actually a “bonus that they are adding on” of $30, which brings the amount to $210. That additional $30 is only available if the member uses a primary care provider that Aetna designates as a “High Value Provider (HVP)”. When the member asks what the additional $30 is from, Christina again repeated that it is a “bonus added on”. Additionally, it is never discussed on the call that the member would need to verify their chronic condition with Aetna to be eligible to use the Extra Supports wallet. Coaching: Christina tells the member that they currently have a supplement plan. This is likely because they are only showing a PDP in Marx. They would have been enrolled in a PDP because they have LIS. In most cases, it is illegal to sell a Supplement plan to someone who has Medicaid. Christina seems to have supplement and PDPs interchanged. | O2: https://mypolicypoint.sharepoint.com/:w:/r/sites/PolicyPointSalesCenter/Shared%20Documents/Member%20Services%20Call%20Flows,%20SOPs,%20and%20docs/Performance/Complaint%20Tracking/CNguyen%2012.01.2025.docx?d=wffea6c23cc3f4fc989aeb54c2c3ff3e5&csf=1&web=1&e=El3dEN
A3: Sandra Stillwell | B3: JT Tellez | C3: https://app.agencybloc.com/individuals/72308257/detail | D3: 45990 | E3: 46045 | G3: 46048.643 | H3: Member Services | I3: Cigna | J3: Member states that they were not told that they would have to pay a deductible for their Mounjaro. | K3: •Drugs - Cost or Coverage | L3: Founded | M3: •Drugs - Cost or Coverage •Benefit Misinformation | N3: At approximately 35:19 into the call, Sandra begins to go over the drug costs. The call was breaking up and the member asked her to repeat herself. Sandra tells the member “drug deductible, tier 1 and tier 2…” and the call cuts in and out. She does say something along the lines of “brand 615” but it is hard to hear on the recording. The member again states that she cannot hear or understand Sandra. Sandra does not repeat any previous information or ask the member what the last thing she heard or understood. Sandra tells the member at approximately 36:40 that she won’t pay more than $47 dollars for her injection. Also, it appears that Sandra seems to think that this is an insulin. Additionally, Sandra sells the plan on a formulary exception for the two drugs that were not on the formulary. We should never sell a plan based on a formulary exception as we cannot guarantee coverage and it sets the incorrect expectation. | O3: https://mypolicypoint.sharepoint.com/:w:/r/sites/PolicyPointSalesCenter/Shared%20Documents/Member%20Services%20Call%20Flows,%20SOPs,%20and%20docs/Performance/Complaint%20Tracking/SStillwell%2011.29.2025.docx?d=w396e9903ad0d4f2683c45da351c5f699&csf=1&web=1&e=ORGHNK
A4: Anthony Boyle | B4: JT Tellez | C4: https://app.agencybloc.com/individuals/71888252/detail | D4: 45968 | E4: 46049 | G4: 46055.653 | H4: Member Services | I4: Humana | J4: Member was under the impression that he would be getting a grocery allowance and that he was qualified for it. | K4: •SSBCI Benefits •Benefit Misinformation | L4: Partially Founded | M4: •SSBCI Benefits •Benefit Misinformation | N4: Anthony ultimately explained to the member what the food card was and what the qualifications are for them. Anthony was off process for much of this call. He opened the call by telling the member “What I'm going to do today is to make sure that you're receiving all the benefits that you are entitled to as a Medicare beneficiary. What that means is seeing about increases in money back on your Social Security. We're making sure that you have the highest food card available in your area that accepts your doctors, hospitals, and drugs, okay?” This improperly sets expectations in the beginning of the call. While Anthony does ultimately do the QA checklist on the plan he enrolled, he presented benefits from three separate plans in this call all at once. He pitched one plan, the member asked questions, and then he gives benefits for two additional plans. He references a plan that gives a giveback as “this plan”, without clarifying which plan he was referring to. This led to some confusion with the member. | O4: https://mypolicypoint-my.sharepoint.com/:w:/r/personal/mthomas_mypolicypoint_com/Documents/Performance%20Tracking/Complaint%20Tracking/ABoyle%2011.07.2025.docx?d=wac80ebfac4164e0e8c9f2874011f0ec1&csf=1&web=1&e=0ZJPHG
A5: Victor Filimonchuk | B5: John St. Fleurant | C5: https://app.agencybloc.com/individuals/73086139/detail | D5: 46029 | E5: 46050 | G5: 46058.661 | H5: Member Services | I5: Gold Kidney Health Plan | J5: The member’s daughter states that she has POA for the member and that the member should not have been allowed to enroll. | K5: •Plan Eligibility •Enrollment Consent | L5: Partially Founded | M5: •Plan Eligibility •Enrollment Consent •Providers - Ancillary •Drugs - Cost or Coverage •Benefit Misinformation | N5: While the member did not indicate that her daughter was POA, she did give indication that another party may provide assistance. On the initial call, Vic asks the member if she makes her own healthcare decisions. She responds “Somewhat”. When Vic probes further, he asks “Do you have someone who is a legal power of attorney who makes these decisions for you?” The member responds with “I can make the decision, but my husband usually, he’s usually there and he’ll tell me ‘yes’ or ‘no’.” Vic then asks if the husband is available and when told no, continues with the process. On the initial call, Vic discusses the member’s current plan. He tells the member that “..in looking at your current level of coverages you you basically have basic coverage meaning exam cleanings x-ray and fluoride treatment it's kind of a basic basic plan as far as coverages are concerned.” This is incorrect. The member’s UHC plan covers both routine and comprehensive dental with a $0 copay. Additionally, there is no benefit maximum on the member’s current plan for these services. This misinformation is repeated at least two other times on this call. On the second call, when Vic is pitching the plan, he states “your doctors is in the plan, your scripts are in the plan.” Vic should have specified the doctor’s name, as he was not able to find one of the providers. Additionally, When Vic was going over prescription drug costs, he did not go through the member’s drugs and let them know about the tiers, quantity limits, or step therapy. Vic refers to an urgent care as a “mini hospital”, which is misleading and inaccurate language. Vic quoted the vision benefit as “$200 for routine eyewear, including lenses, frames, and contact lenses”. The benefit is $200 for lenses and frames and $115 for contact lenses. | O5: https://mypolicypoint-my.sharepoint.com/:w:/r/personal/mthomas_mypolicypoint_com/Documents/Performance%20Tracking/Complaint%20Tracking/VFilimonchuk%2001.07.2026.docx?d=wc70b7eba4d4d48cc910471ffa1e8b941&csf=1&web=1&e=aHWMuV
A6: Tasia Clark | B6: Nesia Jefferies | C6: https://app.agencybloc.com/individuals/73450699/detail | D6: 46043 | E6: 46057 | G6: 46059.676 | H6: Member Services | I6: Devoted Health | J6: The member states that she was not told about the qualifications for the SSBCI benefit. | K6: •SSBCI Benefits •Benefit Misinformation | L6: Founded | M6: •SSBCI Benefits •Providers - Ancillary •Benefit Misinformation | N6: When Tasia asked the member about chronic conditions, the member states “No, I am as healthy as a horse”. When she asked the member about the primary care doctor or specialists, the member indicates that they do not see any doctors. The member also indicates that they do not take any prescriptions. These should have all been flags that the member does not have any current chronic conditions. When Tasia pitches the plan, she calls out that the member states that she is healthy and then pitches the SSBCI benefit. Additionally, in pitching the plan, the Tasia states that the proposed plan increases the dental. However, the member’s plan does not have a maximum benefit limit and the Devoted has a maximum benefit of $2000. | O6: https://mypolicypoint-my.sharepoint.com/:w:/r/personal/mthomas_mypolicypoint_com/Documents/Performance%20Tracking/Complaint%20Tracking/TClark%2001.21.2026.docx?d=w52b0da9210c84b799fe21d66907dd8db&csf=1&web=1&e=F920cI
A7: Kylie DeMarino | B7: JT Tellez | C7: https://app.agencybloc.com/individuals/73086180/detail | D7: 46029 | E7: 46050 | G7: 46063.496 | H7: Member Services | I7: Devoted Health | J7: Member states that they were unaware that they were enrolling in a new plan, did not agree, and did not want to change. | K7: •Enrollment Consent | L7: Unfounded | M7: •Enrollment Consent | N7: In listening to this call, the member indicated that they make their own healthcare decisions when asked. The member appeared to be lucid and actively engaged in the call throughout its entirety. Kylie completed the process compliantly and got the necessary agreements. | O7: https://mypolicypoint-my.sharepoint.com/:w:/r/personal/mthomas_mypolicypoint_com/Documents/Performance%20Tracking/Complaint%20Tracking/KDeMarino%2001.07.2026.docx?d=w7ce1fe0d067f4e54b55c31f0b0bd9ea4&csf=1&web=1&e=5ADbti
A8: Duane Kipp | B8: Nesia Jefferies | C8: https://app.agencybloc.com/individuals/72075385/detail | D8: 45980 | E8: 46059 | G8: 46064.49 | H8: Member Services | I8: United Healthcare | J8: The member indicated that they had three brain tumors and does not remember the enrollment. | K8: •Plan Eligibility •Enrollment Consent | L8: Founded | M8: •Plan Eligibility •Enrollment Consent •Providers - Medical | N8: In listening to the two calls that comprised this enrollment, there were more than 15 instances where the member mentioned memory loss, inability to understand, or confusion. While the member did not indicate that they had a POA these instances call into question the member’s capacity to understand and consent to enrollment compliantly. At approximately 50:26 into the second call, for example, the member states “My brain isn’t letting me remember things right now.” At approximately 1:01:28 into the second call when Duane asks the member if they understand the benefits prior to starting the application, she responds “I can’t remember them because of those tumors. But I’m sure it’s good.” During the disclaimers, she states “I’m I’m kind of getting confused a little bit.” After Duane had completed the enrollment, the member states “I’ll look at UnitedHealthcare, and I’ll figure out which one I want” which is an indicator that she did not understand that she had been enrolled. Throughout the call, there were additional indicators that the member was not understanding or in a capacity to complete the enrollment compliantly. After the first call dropped and Duane called her back immediately, she stated she had no idea what he was talking about. At approximately 1:03:50 on the second call, the member was unable to answer if Louise was her middle name or part of her first name. At approximately 1:10:14 into the second call, she states, “I’m going to get hollered at by my son” and at 1:10:26 goes on to say “He’s very protective because he knows that I’ve been through, and he knows I don’t understand a lot of this stuff.” At approximately 1:03:50 into the second call, the member was unable to answer if Louise was her middle name or part of her first name. After Duane had completed the enrollment, the member states “I’ll look at UnitedHealthcare, and I’ll figure out which one I want” which is an indicator that she did not understand that she had been enrolled. Additionally, when Duane pitched this plan he told the member that her doctor, Dr. Hundley, was in-network. I am not showing this provider to be in-network on Sunfire or on the carrier’s portal. There are also concerns about rapid disenrollment on this call. At approximately 1:34:16 on the second call the member asks, “Let’s say I get all the information and dI read it and then I change my mind. I don’t want to do it”. Duane explains to her to call him at that time, rather than reaffirm the plan benefits. The member asks again at 1:50:27 “If I go over this and I decide to change my mind, will I be free?”. Duane again tells her to call him. At 1:51:06 into the call, Duane tells the member “There is what’s called OEP. So, you’re able to update the policies then as well. It gives you a one-chance redo when you come through annual enrollment. So, that is an option, okay?”. | O8: https://mypolicypoint-my.sharepoint.com/:w:/r/personal/mthomas_mypolicypoint_com/Documents/Performance%20Tracking/Complaint%20Tracking/DKipp%2011.19.2025.docx?d=wfd2c46ce9d444e0188a9cf5d5c388137&csf=1&web=1&e=S6sitM
A9: Lauren Wyke | B9: Michelle Thomas | C9: https://app.agencybloc.com/individuals/72084054/detail | D9: 46050 | E9: 46050 | G9: 46064.693 | H9: Member Services | I9: Gold Kidney Health Plan | J9: Member states that Lauren’s behavior towards the Gold Kidney Member Services team was inappropriate. | K9: •Agent Behavior | L9: Unfounded | M9: •Agent Behavior | N9: Lauren called Gold Kidney with the member on the line to discuss multiple concerns. She asked the Gold Kidney agent if the chronic condition was verified. The GK agent Sima gave conflicting information which led Lauren to be more firm with the agent. She was not aggressive or inappropriate. The member became very frustrated and Lauren attempted to de-escalate. The member became escalated at other points in the call and Lauren appropriately de-escalates. In the call with AndMore at approximately 43:40, the AndMore agent states “we don’t have any record, like, well on my screen. I’m not gonna say he didn’t do it so don’t go like this, don’t go there”. Lauren politely said “Sir, we don’t need to say things like that.” The AndMore agent’s behavior just continues to deteriorate. The agent becomes very condescending and starts to shout at her. Lauren unintentionally had misgendered the AndMore representative, and she sincerely apologized. The AndMore agent continues to escalate the situation, but Lauren was ultimately able to resolve it and move the call forward. | O9: https://mypolicypoint-my.sharepoint.com/:w:/r/personal/mthomas_mypolicypoint_com/Documents/Performance%20Tracking/Complaint%20Tracking/LWyke%2001.28.2026.docx?d=w476c6fd712de499496b12b81263ace61&csf=1&web=1&e=2gXVCk
